Workbook

Sheet Events
A1: EventID | B1: Event | C1: EventType | D1: EventCategory | E1: EventRanking | F1: Hall | G1: Skillset1 | H1: Skillset2 | I1: Employees | J1: Date | K1: ShiftBegins | L1: ShiftEnds
A2: 1 | B2: JS | C2: EB | D2: =_xlfn.XLOOKUP(C2,EventTypes!A:A,EventTypes!B:B,"") -> Basic | E2: =_xlfn.XLOOKUP(C2,EventTypes!A:A,EventTypes!D:D,"") -> 70 | F2: =_xlfn.XLOOKUP(C2,EventTypes!A:A,EventTypes!C:C,"") -> EB | G2: =_xlfn.XLOOKUP(C2,EventTypes!A:A,EventTypes!E:E,"") -> 1 | H2: =_xlfn.XLOOKUP(C2,EventTypes!A:A,EventTypes!F:F,"") -> 4 | I2: 10 | J2: 46082 | K2: 0.70833333 | L2: 0.83333333
A3: 2 | B3: Sinfó | C3: Sinfó | D3: =_xlfn.XLOOKUP(C3,EventTypes!A:A,EventTypes!B:B,"") -> Basic | E3: =_xlfn.XLOOKUP(C3,EventTypes!A:A,EventTypes!D:D,"") -> 50 | F3: =_xlfn.XLOOKUP(C3,EventTypes!A:A,EventTypes!C:C,"") -> EB | G3: 1 | H3: =_xlfn.XLOOKUP(C3,EventTypes!A:A,EventTypes!F:F,"") -> 3 | I3: 12 | J3: 46086 | K3: 0.77083333 | L3: 0.89583333
A4: 3 | B4: Tón | C4: KL | D4: =_xlfn.XLOOKUP(C4,EventTypes!A:A,EventTypes!B:B,"") -> Basic | E4: =_xlfn.XLOOKUP(C4,EventTypes!A:A,EventTypes!D:D,"") -> 40 | F4: =_xlfn.XLOOKUP(C4,EventTypes!A:A,EventTypes!C:C,"") -> KL | G4: =_xlfn.XLOOKUP(C4,EventTypes!A:A,EventTypes!E:E,"") -> 0 | H4: =_xlfn.XLOOKUP(C4,EventTypes!A:A,EventTypes!F:F,"") -> 1 | I4: 1 | J4: 46086 | K4: 0.79166667 | L4: 0.91666667
A5: 4 | B5: RMF | C5: NL | D5: =_xlfn.XLOOKUP(C5,EventTypes!A:A,EventTypes!B:B,"") -> Basic | E5: =_xlfn.XLOOKUP(C5,EventTypes!A:A,EventTypes!D:D,"") -> 80 | F5: =_xlfn.XLOOKUP(C5,EventTypes!A:A,EventTypes!C:C,"") -> NL | G5: 1 | H5: =_xlfn.XLOOKUP(C5,EventTypes!A:A,EventTypes!F:F,"") -> 0 | I5: 3 | J5: 46087 | K5: 0.77083333 | L5: 0.875
A6: 5 | B6: HAM | C6: Partý EB | D6: =_xlfn.XLOOKUP(C6,EventTypes!A:A,EventTypes!B:B,"") -> Party | E6: =_xlfn.XLOOKUP(C6,EventTypes!A:A,EventTypes!D:D,"") -> 50 | F6: =_xlfn.XLOOKUP(C6,EventTypes!A:A,EventTypes!C:C,"") -> EB | G6: =_xlfn.XLOOKUP(C6,EventTypes!A:A,EventTypes!E:E,"") -> 1 | H6: =_xlfn.XLOOKUP(C6,EventTypes!A:A,EventTypes!F:F,"") -> 6 | I6: 11 | J6: 46087 | K6: 0.79166667 | L6: 0.95833333
A7: 6 | B7: IS | C7: EB | D7: =_xlfn.XLOOKUP(C7,EventTypes!A:A,EventTypes!B:B,"") -> Basic | E7: =_xlfn.XLOOKUP(C7,EventTypes!A:A,EventTypes!D:D,"") -> 70 | F7: =_xlfn.XLOOKUP(C7,EventTypes!A:A,EventTypes!C:C,"") -> EB | G7: =_xlfn.XLOOKUP(C7,EventTypes!A:A,EventTypes!E:E,"") -> 1 | H7: =_xlfn.XLOOKUP(C7,EventTypes!A:A,EventTypes!F:F,"") -> 4 | I7: 7 | J7: 46088 | K7: 0.79166667 | L7: 0.95833333
A8: 7 | B8: IS | C8: Fatahengi | D8: =_xlfn.XLOOKUP(C8,EventTypes!A:A,EventTypes!B:B,"") -> Fatahengi | E8: =_xlfn.XLOOKUP(C8,EventTypes!A:A,EventTypes!D:D,"") -> 80 | F8: =_xlfn.XLOOKUP(C8,EventTypes!A:A,EventTypes!C:C,"") -> Fatahengi | G8: =_xlfn.XLOOKUP(C8,EventTypes!A:A,EventTypes!E:E,"") -> 0 | H8: =_xlfn.XLOOKUP(C8,EventTypes!A:A,EventTypes!F:F,"") -> 0 | I8: 10 | J8: 46088 | K8: 0.52083333 | L8: 0.75
A9: 8 | B9: PD | C9: EB | D9: =_xlfn.XLOOKUP(C9,EventTypes!A:A,EventTypes!B:B,"") -> Basic | E9: =_xlfn.XLOOKUP(C9,EventTypes!A:A,EventTypes!D:D,"") -> 70 | F9: =_xlfn.XLOOKUP(C9,EventTypes!A:A,EventTypes!C:C,"") -> EB | G9: =_xlfn.XLOOKUP(C9,EventTypes!A:A,EventTypes!E:E,"") -> 1 | H9: =_xlfn.XLOOKUP(C9,EventTypes!A:A,EventTypes!F:F,"") -> 4 | I9: =_xlfn.XLOOKUP(C9,EventTypes!A:A,EventTypes!G:G,"") -> 11 | J9: 46090 | K9: 0.79166667 | L9: 0.91666667
A10: 9 | B10: Sinfó | C10: Sinfó | D10: =_xlfn.XLOOKUP(C10,EventTypes!A:A,EventTypes!B:B,"") -> Basic | E10: =_xlfn.XLOOKUP(C10,EventTypes!A:A,EventTypes!D:D,"") -> 50 | F10: =_xlfn.XLOOKUP(C10,EventTypes!A:A,EventTypes!C:C,"") -> EB | G10: =_xlfn.XLOOKUP(C10,EventTypes!A:A,EventTypes!E:E,"") -> 1 | H10: =_xlfn.XLOOKUP(C10,EventTypes!A:A,EventTypes!F:F,"") -> 3 | I10: 11 | J10: 46093 | K10: 0.77083333 | L10: 0.89583333
A11: 10 | B11: Sinfó | C11: Sinfó | D11: =_xlfn.XLOOKUP(C11,EventTypes!A:A,EventTypes!B:B,"") -> Basic | E11: =_xlfn.XLOOKUP(C11,EventTypes!A:A,EventTypes!D:D,"") -> 50 | F11: =_xlfn.XLOOKUP(C11,EventTypes!A:A,EventTypes!C:C,"") -> EB | G11: =_xlfn.XLOOKUP(C11,EventTypes!A:A,EventTypes!E:E,"") -> 1 | H11: =_xlfn.XLOOKUP(C11,EventTypes!A:A,EventTypes!F:F,"") -> 3 | I11: 7 | J11: 46094 | K11: 0.70833333 | L11: 0.83333333
A12: 11 | B12: SB | C12: NL | D12: =_xlfn.XLOOKUP(C12,EventTypes!A:A,EventTypes!B:B,"") -> Basic | E12: =_xlfn.XLOOKUP(C12,EventTypes!A:A,EventTypes!D:D,"") -> 80 | F12: =_xlfn.XLOOKUP(C12,EventTypes!A:A,EventTypes!C:C,"") -> NL | G12: 0 | H12: =_xlfn.XLOOKUP(C12,EventTypes!A:A,EventTypes!F:F,"") -> 0 | I12: 2 | J12: 46094 | K12: 0.75 | L12: 0.91666667
A13: 12 | B13: GB | C13: Partý EB | D13: =_xlfn.XLOOKUP(C13,EventTypes!A:A,EventTypes!B:B,"") -> Party | E13: =_xlfn.XLOOKUP(C13,EventTypes!A:A,EventTypes!D:D,"") -> 50 | F13: =_xlfn.XLOOKUP(C13,EventTypes!A:A,EventTypes!C:C,"") -> EB | G13: =_xlfn.XLOOKUP(C13,EventTypes!A:A,EventTypes!E:E,"") -> 1 | H13: =_xlfn.XLOOKUP(C13,EventTypes!A:A,EventTypes!F:F,"") -> 6 | I13: 12 | J13: 46095 | K13: 0.75 | L13: 0.91666667
A14: 13 | B14: ITV | C14: SB | D14: =_xlfn.XLOOKUP(C14,EventTypes!A:A,EventTypes!B:B,"") -> Basic | E14: =_xlfn.XLOOKUP(C14,EventTypes!A:A,EventTypes!D:D,"") -> 80 | F14: =_xlfn.XLOOKUP(C14,EventTypes!A:A,EventTypes!C:C,"") -> SB | G14: 0 | H14: =_xlfn.XLOOKUP(C14,EventTypes!A:A,EventTypes!F:F,"") -> 1 | I14: 2 | J14: 46099 | K14: 0.75 | L14: 0.91666667
A15: 14 | B15: DS | C15: EB | D15: =_xlfn.XLOOKUP(C15,EventTypes!A:A,EventTypes!B:B,"") -> Basic | E15: =_xlfn.XLOOKUP(C15,EventTypes!A:A,EventTypes!D:D,"") -> 70 | F15: =_xlfn.XLOOKUP(C15,EventTypes!A:A,EventTypes!C:C,"") -> EB | G15: =_xlfn.XLOOKUP(C15,EventTypes!A:A,EventTypes!E:E,"") -> 1 | H15: =_xlfn.XLOOKUP(C15,EventTypes!A:A,EventTypes!F:F,"") -> 4 | I15: 7 | J15: 46100 | K15: 0.79166667 | L15: 0.91666667
A16: 15 | B16: DS | C16: Partý EB | D16: =_xlfn.XLOOKUP(C16,EventTypes!A:A,EventTypes!B:B,"") -> Party | E16: =_xlfn.XLOOKUP(C16,EventTypes!A:A,EventTypes!D:D,"") -> 50 | F16: =_xlfn.XLOOKUP(C16,EventTypes!A:A,EventTypes!C:C,"") -> EB | G16: =_xlfn.XLOOKUP(C16,EventTypes!A:A,EventTypes!E:E,"") -> 1 | H16: =_xlfn.XLOOKUP(C16,EventTypes!A:A,EventTypes!F:F,"") -> 6 | I16: 12 | J16: 46101 | K16: 0.79166667 | L16: 0.95833333
A17: 16 | B17: MT | C17: NL | D17: =_xlfn.XLOOKUP(C17,EventTypes!A:A,EventTypes!B:B,"") -> Basic | E17: =_xlfn.XLOOKUP(C17,EventTypes!A:A,EventTypes!D:D,"") -> 80 | F17: =_xlfn.XLOOKUP(C17,EventTypes!A:A,EventTypes!C:C,"") -> NL | G17: 0 | H17: =_xlfn.XLOOKUP(C17,EventTypes!A:A,EventTypes!F:F,"") -> 0 | I17: 1 | J17: 46101 | K17: 0.77083333 | L17: 0.91666667
A18: 17 | B18: MT | C18: NL | D18: =_xlfn.XLOOKUP(C18,EventTypes!A:A,EventTypes!B:B,"") -> Basic | E18: =_xlfn.XLOOKUP(C18,EventTypes!A:A,EventTypes!D:D,"") -> 80 | F18: =_xlfn.XLOOKUP(C18,EventTypes!A:A,EventTypes!C:C,"") -> NL | G18: 0 | H18: =_xlfn.XLOOKUP(C18,EventTypes!A:A,EventTypes!F:F,"") -> 0 | I18: 1 | J18: 46102 | K18: 0.77083333 | L18: 0.89583333
A19: 18 | B19: MT | C19: NL | D19: =_xlfn.XLOOKUP(C19,EventTypes!A:A,EventTypes!B:B,"") -> Basic | E19: =_xlfn.XLOOKUP(C19,EventTypes!A:A,EventTypes!D:D,"") -> 80 | F19: =_xlfn.XLOOKUP(C19,EventTypes!A:A,EventTypes!C:C,"") -> NL | G19: 0 | H19: =_xlfn.XLOOKUP(C19,EventTypes!A:A,EventTypes!F:F,"") -> 0 | I19: 2 | J19: 46103 | K19: 0.77083333 | L19: 0.875
A20: 19 | B20: MT | C20: NL | D20: =_xlfn.XLOOKUP(C20,EventTypes!A:A,EventTypes!B:B,"") -> Basic | E20: =_xlfn.XLOOKUP(C20,EventTypes!A:A,EventTypes!D:D,"") -> 80 | F20: =_xlfn.XLOOKUP(C20,EventTypes!A:A,EventTypes!C:C,"") -> NL | G20: 0 | H20: =_xlfn.XLOOKUP(C20,EventTypes!A:A,EventTypes!F:F,"") -> 0 | I20: 1 | J20: 46104 | K20: 0.77083333 | L20: 0.875
A21: 20 | B21: MT | C21: NL | D21: =_xlfn.XLOOKUP(C21,EventTypes!A:A,EventTypes!B:B,"") -> Basic | E21: =_xlfn.XLOOKUP(C21,EventTypes!A:A,EventTypes!D:D,"") -> 80 | F21: =_xlfn.XLOOKUP(C21,EventTypes!A:A,EventTypes!C:C,"") -> NL | G21: 1 | H21: =_xlfn.XLOOKUP(C21,EventTypes!A:A,EventTypes!F:F,"") -> 0 | I21: 2 | J21: 46109 | K21: 0.66666667 | L21: 0.91666667
A22: 21 | B22: PF | C22: Partý EB | D22: =_xlfn.XLOOKUP(C22,EventTypes!A:A,EventTypes!B:B,"") -> Party | E22: =_xlfn.XLOOKUP(C22,EventTypes!A:A,EventTypes!D:D,"") -> 50 | F22: =_xlfn.XLOOKUP(C22,EventTypes!A:A,EventTypes!C:C,"") -> EB | G22: 1 | H22: =_xlfn.XLOOKUP(C22,EventTypes!A:A,EventTypes!F:F,"") -> 6 | I22: 12 | J22: 46102 | K22: 0.83333333 | L22: 0
A23: 22 | B23: RP | C23: Partý EB | D23: =_xlfn.XLOOKUP(C23,EventTypes!A:A,EventTypes!B:B,"") -> Party | E23: =_xlfn.XLOOKUP(C23,EventTypes!A:A,EventTypes!D:D,"") -> 50 | F23: =_xlfn.XLOOKUP(C23,EventTypes!A:A,EventTypes!C:C,"") -> EB | G23: 1 | H23: =_xlfn.XLOOKUP(C23,EventTypes!A:A,EventTypes!F:F,"") -> 6 | I23: 12 | J23: 46108 | K23: 0.79166667 | L23: 0.91666667
A24: 23 | B24: Fam | C24: EB | D24: =_xlfn.XLOOKUP(C24,EventTypes!A:A,EventTypes!B:B,"") -> Basic | E24: =_xlfn.XLOOKUP(C24,EventTypes!A:A,EventTypes!D:D,"") -> 70 | F24: =_xlfn.XLOOKUP(C24,EventTypes!A:A,EventTypes!C:C,"") -> EB | G24: =_xlfn.XLOOKUP(C24,EventTypes!A:A,EventTypes!E:E,"") -> 1 | H24: =_xlfn.XLOOKUP(C24,EventTypes!A:A,EventTypes!F:F,"") -> 4 | I24: 7 | J24: 46110 | K24: 0.58333333 | L24: 0.75
A25: 24 | B25: HT | C25: How To | D25: =_xlfn.XLOOKUP(C25,EventTypes!A:A,EventTypes!B:B,"") -> Solo | E25: =_xlfn.XLOOKUP(C25,EventTypes!A:A,EventTypes!D:D,"") -> 100 | F25: =_xlfn.XLOOKUP(C25,EventTypes!A:A,EventTypes!C:C,"") -> KL | G25: =_xlfn.XLOOKUP(C25,EventTypes!A:A,EventTypes!E:E,"") -> 0 | H25: =_xlfn.XLOOKUP(C25,EventTypes!A:A,EventTypes!F:F,"") -> 0 | I25: 1 | J25: 46095 | K25: 0.75 | L25: 0.91666667
A26: 25 | B26: HT | C26: How To | D26: =_xlfn.XLOOKUP(C26,EventTypes!A:A,EventTypes!B:B,"") -> Solo | E26: =_xlfn.XLOOKUP(C26,EventTypes!A:A,EventTypes!D:D,"") -> 100 | F26: =_xlfn.XLOOKUP(C26,EventTypes!A:A,EventTypes!C:C,"") -> KL | G26: =_xlfn.XLOOKUP(C26,EventTypes!A:A,EventTypes!E:E,"") -> 0 | H26: =_xlfn.XLOOKUP(C26,EventTypes!A:A,EventTypes!F:F,"") -> 0 | I26: 1 | J26: 46102 | K26: 0.75 | L26: 0.91666667
A27: 26 | B27: HT | C27: How To | D27: =_xlfn.XLOOKUP(C27,EventTypes!A:A,EventTypes!B:B,"") -> Solo | E27: =_xlfn.XLOOKUP(C27,EventTypes!A:A,EventTypes!D:D,"") -> 100 | F27: =_xlfn.XLOOKUP(C27,EventTypes!A:A,EventTypes!C:C,"") -> KL | G27: =_xlfn.XLOOKUP(C27,EventTypes!A:A,EventTypes!E:E,"") -> 0 | H27: =_xlfn.XLOOKUP(C27,EventTypes!A:A,EventTypes!F:F,"") -> 0 | I27: 1 | J27: 46109 | K27: 0.75 | L27: 0.91666667
A28: 27 | B28: EÁ | C28: Barna KL | D28: =_xlfn.XLOOKUP(C28,EventTypes!A:A,EventTypes!B:B,"") -> Barna | E28: =_xlfn.XLOOKUP(C28,EventTypes!A:A,EventTypes!D:D,"") -> 80 | F28: =_xlfn.XLOOKUP(C28,EventTypes!A:A,EventTypes!C:C,"") -> KL | G28: =_xlfn.XLOOKUP(C28,EventTypes!A:A,EventTypes!E:E,"") -> 0 | H28: =_xlfn.XLOOKUP(C28,EventTypes!A:A,EventTypes!F:F,"") -> 1 | I28: 2 | J28: 46088 | K28: 0.5 | L28: 0.66666667
A29: 28 | B29: EÁ | C29: Barna KL | D29: =_xlfn.XLOOKUP(C29,EventTypes!A:A,EventTypes!B:B,"") -> Barna | E29: =_xlfn.XLOOKUP(C29,EventTypes!A:A,EventTypes!D:D,"") -> 80 | F29: =_xlfn.XLOOKUP(C29,EventTypes!A:A,EventTypes!C:C,"") -> KL | G29: 0 | H29: =_xlfn.XLOOKUP(C29,EventTypes!A:A,EventTypes!F:F,"") -> 1 | I29: 2 | J29: 46102 | K29: 0.5 | L29: 0.66666667
A30: 29 | B30: EÁ | C30: Barna KL | D30: =_xlfn.XLOOKUP(C30,EventTypes!A:A,EventTypes!B:B,"") -> Barna | E30: =_xlfn.XLOOKUP(C30,EventTypes!A:A,EventTypes!D:D,"") -> 80 | F30: =_xlfn.XLOOKUP(C30,EventTypes!A:A,EventTypes!C:C,"") -> KL | G30: =_xlfn.XLOOKUP(C30,EventTypes!A:A,EventTypes!E:E,"") -> 0 | H30: =_xlfn.XLOOKUP(C30,EventTypes!A:A,EventTypes!F:F,"") -> 1 | I30: 2 | J30: 46109 | K30: 0.5 | L30: 0.66666667
A31: 30 | B31: Múlinn | C31: Múlinn | D31: =_xlfn.XLOOKUP(C31,EventTypes!A:A,EventTypes!B:B,"") -> Solo | E31: =_xlfn.XLOOKUP(C31,EventTypes!A:A,EventTypes!D:D,"") -> 80 | F31: =_xlfn.XLOOKUP(C31,EventTypes!A:A,EventTypes!C:C,"") -> BL | G31: =_xlfn.XLOOKUP(C31,EventTypes!A:A,EventTypes!E:E,"") -> 0 | H31: =_xlfn.XLOOKUP(C31,EventTypes!A:A,EventTypes!F:F,"") -> 0 | I31: 1 | J31: 46085 | K31: 0.79166667 | L31: 0.91666667
A32: 31 | B32: Múlinn | C32: Múlinn | D32: =_xlfn.XLOOKUP(C32,EventTypes!A:A,EventTypes!B:B,"") -> Solo | E32: =_xlfn.XLOOKUP(C32,EventTypes!A:A,EventTypes!D:D,"") -> 80 | F32: =_xlfn.XLOOKUP(C32,EventTypes!A:A,EventTypes!C:C,"") -> BL | G32: =_xlfn.XLOOKUP(C32,EventTypes!A:A,EventTypes!E:E,"") -> 0 | H32: =_xlfn.XLOOKUP(C32,EventTypes!A:A,EventTypes!F:F,"") -> 0 | I32: 1 | J32: 46092 | K32: 0.79166667 | L32: 0.91666667
A33: 32 | B33: Múlinn | C33: Múlinn | D33: =_xlfn.XLOOKUP(C33,EventTypes!A:A,EventTypes!B:B,"") -> Solo | E33: =_xlfn.XLOOKUP(C33,EventTypes!A:A,EventTypes!D:D,"") -> 80 | F33: =_xlfn.XLOOKUP(C33,EventTypes!A:A,EventTypes!C:C,"") -> BL | G33: 0 | H33: =_xlfn.XLOOKUP(C33,EventTypes!A:A,EventTypes!F:F,"") -> 0 | I33: 1 | J33: 46099 | K33: 0.79166667 | L33: 0.91666667
A34: 33 | B34: Múlinn | C34: Múlinn | D34: =_xlfn.XLOOKUP(C34,EventTypes!A:A,EventTypes!B:B,"") -> Solo | E34: =_xlfn.XLOOKUP(C34,EventTypes!A:A,EventTypes!D:D,"") -> 80 | F34: =_xlfn.XLOOKUP(C34,EventTypes!A:A,EventTypes!C:C,"") -> BL | G34: 0 | H34: =_xlfn.XLOOKUP(C34,EventTypes!A:A,EventTypes!F:F,"") -> 0 | I34: 1 | J34: 46106 | K34: 0.79166667 | L34: 0.91666667
A35: 34 | B35: UR | C35: KL | D35: =_xlfn.XLOOKUP(C35,EventTypes!A:A,EventTypes!B:B,"") -> Basic | E35: =_xlfn.XLOOKUP(C35,EventTypes!A:A,EventTypes!D:D,"") -> 40 | F35: =_xlfn.XLOOKUP(C35,EventTypes!A:A,EventTypes!C:C,"") -> KL | G35: 0 | H35: =_xlfn.XLOOKUP(C35,EventTypes!A:A,EventTypes!F:F,"") -> 1 | I35: 1 | J35: 46091 | K35: 0.79166667 | L35: 0.91666667
A36: 35 | B36: KD | C36: NL | D36: =_xlfn.XLOOKUP(C36,EventTypes!A:A,EventTypes!B:B,"") -> Basic | E36: =_xlfn.XLOOKUP(C36,EventTypes!A:A,EventTypes!D:D,"") -> 80 | F36: =_xlfn.XLOOKUP(C36,EventTypes!A:A,EventTypes!C:C,"") -> NL | G36: 0 | H36: =_xlfn.XLOOKUP(C36,EventTypes!A:A,EventTypes!F:F,"") -> 0 | I36: 2 | J36: 46098 | K36: 0.79166667 | L36: 0.91666667
A37: 36 | B37: JN | C37: NL | D37: =_xlfn.XLOOKUP(C37,EventTypes!A:A,EventTypes!B:B,"") -> Basic | E37: =_xlfn.XLOOKUP(C37,EventTypes!A:A,EventTypes!D:D,"") -> 80 | F37: =_xlfn.XLOOKUP(C37,EventTypes!A:A,EventTypes!C:C,"") -> NL | G37: 0 | H37: =_xlfn.XLOOKUP(C37,EventTypes!A:A,EventTypes!F:F,"") -> 0 | I37: 1 | J37: 46097 | K37: 0.79166667 | L37: 0.91666667
A38: 37 | B38: K&B | C38: Barna KL | D38: =_xlfn.XLOOKUP(C38,EventTypes!A:A,EventTypes!B:B,"") -> Barna | E38: =_xlfn.XLOOKUP(C38,EventTypes!A:A,EventTypes!D:D,"") -> 80 | F38: =_xlfn.XLOOKUP(C38,EventTypes!A:A,EventTypes!C:C,"") -> KL | G38: =_xlfn.XLOOKUP(C38,EventTypes!A:A,EventTypes!E:E,"") -> 0 | H38: =_xlfn.XLOOKUP(C38,EventTypes!A:A,EventTypes!F:F,"") -> 1 | I38: 2 | J38: 46103 | K38: 0.5 | L38: 0.66666667
A39: 38 | B39: Svef | C39: SB | D39: =_xlfn.XLOOKUP(C39,EventTypes!A:A,EventTypes!B:B,"") -> Basic | E39: =_xlfn.XLOOKUP(C39,EventTypes!A:A,EventTypes!D:D,"") -> 80 | F39: =_xlfn.XLOOKUP(C39,EventTypes!A:A,EventTypes!C:C,"") -> SB | G39: 0 | H39: =_xlfn.XLOOKUP(C39,EventTypes!A:A,EventTypes!F:F,"") -> 1 | I39: 1 | J39: 46107 | K39: 0.70833333 | L39: 0.83333333
A40: 39 | B40: Sígildir | C40: Sígildir | D40: =_xlfn.XLOOKUP(C40,EventTypes!A:A,EventTypes!B:B,"") -> Solo | E40: =_xlfn.XLOOKUP(C40,EventTypes!A:A,EventTypes!D:D,"") -> 90 | F40: =_xlfn.XLOOKUP(C40,EventTypes!A:A,EventTypes!C:C,"") -> NL | G40: =_xlfn.XLOOKUP(C40,EventTypes!A:A,EventTypes!E:E,"") -> 0 | H40: =_xlfn.XLOOKUP(C40,EventTypes!A:A,EventTypes!F:F,"") -> 0 | I40: 2 | J40: 46103 | K40: 0.625 | L40: 0.79166667
...

Sheet Employees
A1: EmployeeID | B1: EmployeeName | C1: Skillset
A2: 1 | B2: Agnes Anna | C2: 2
A3: 2 | B3: Alda/ Miðó | C3: 2
A4: 3 | B4: Anna Soffía | C4: 2
A5: 4 | B5: Arnar Ragn | C5: 2
A6: 5 | B6: Auður | C6: 2
A7: 6 | B7: Ágústa | C7: 2
A8: 7 | B8: Daníel | C8: 2
A9: 8 | B9: Elísabet | C9: 2
A10: 9 | B10: Elmar | C10: 2
A11: 10 | B11: Erna | C11: 2
A12: 11 | B12: Gaukur | C12: 2
A13: 12 | B13: Gréta | C13: 2
... A42: 41 | B42: Þórey | C42: 1

Sheet DaysOff
A1: EmployeeID | B1: 46082 | C1: 46083 | D1: 46084 | E1: 46085 | F1: 46086 | G1: 46087 | H1: 46088 | I1: 46089 | J1: 46090 | K1: 46091 | L1: 46092 | M1: 46093 | N1: 46094 | O1: 46095 | P1: 46096 | Q1: 46097 | R1: 46098 | S1: 46099 | T1: 46100 | U1: 46101 | V1: 46102 | W1: 46103 | X1: 46104 | Y1: 46105 | Z1: 46106 | AA1: 46107 | AB1: 46108 | AC1: 46109 | AD1: 46110 | AE1: 46111 | AF1: 46112
A2: 1 | B2: 1 | C2: 1 | D2: 1 | E2: 1 | F2: 1 | G2: 1 | H2: 1 | I2: 1 | J2: 1 | K2: 1 | L2: 1 | M2: 1 | N2: 1 | O2: 1 | P2: 1 | Q2: 1 | R2: 1 | S2: 1 | T2: 1 | U2: 1 | V2: 1 | W2: 1 | X2: 1 | Y2: 1 | Z2: 1 | AA2: 1 | AB2: 1 | AC2: 1 | AD2: 1 | AE2: 1 | AF2: 1
A3: 2
A4: 3 | N4: 1 | O4: 1 | P4: 1
A5: 4 | N5: 1 | O5: 1 | P5: 1
A6: 5
A7: 6 | B7: 1 | C7: 1 | D7: 1 | E7: 1 | F7: 1 | G7: 1 | H7: 1 | I7: 1 | J7: 1 | K7: 1 | L7: 1 | M7: 1 | N7: 1 | O7: 1 | P7: 1 | Q7: 1 | R7: 1 | S7: 1 | T7: 1 | U7: 1 | V7: 1 | W7: 1 | X7: 1 | Y7: 1 | Z7: 1 | AA7: 1 | AB7: 1 | AC7: 1 | AD7: 1 | AE7: 1 | AF7: 1
A8: 7 | B8: 1 | C8: 1 | D8: 1 | E8: 1 | F8: 1 | G8: 1 | H8: 1 | I8: 1 | J8: 1 | K8: 1 | L8: 1 | M8: 1 | N8: 1 | O8: 1 | P8: 1 | Q8: 1 | R8: 1 | S8: 1 | T8: 1 | U8: 1 | V8: 1 | W8: 1 | X8: 1 | Y8: 1 | Z8: 1 | AA8: 1 | AB8: 1 | AC8: 1 | AD8: 1 | AE8: 1 | AF8: 1
A9: 8
A10: 9 | B10: 1 | K10: 1 | M10: 1 | N10: 1 | O10: 1 | P10: 1 | R10: 1 | Y10: 1 | AF10: 1
A11: 10
A12: 11
A13: 12
A14: 13 | B14: 1 | C14: 1
A15: 14 | U15: 1
A16: 15
A17: 16 | B17: 1
A18: 17
A19: 18 | B19: 1 | C19: 1 | D19: 1 | E19: 1 | F19: 1 | G19: 1 | H19: 1 | I19: 1 | J19: 1 | K19: 1 | L19: 1 | M19: 1 | N19: 1 | O19: 1 | P19: 1
A20: 19
A21: 20
A22: 21 | B22: 1 | C22: 1 | D22: 1 | E22: 1 | F22: 1 | G22: 1 | H22: 1 | I22: 1 | J22: 1 | K22: 1 | L22: 1 | M22: 1 | N22: 1 | O22: 1 | P22: 1 | Q22: 1 | R22: 1 | S22: 1 | T22: 1 | U22: 1 | V22: 1 | W22: 1 | X22: 1 | Y22: 1 | Z22: 1 | AA22: 1 | AB22: 1 | AC22: 1 | AD22: 1 | AE22: 1 | AF22: 1
A23: 22 | B23: 1 | C23: 1
A24: 23 | B24: 1 | C24: 1 | D24: 1 | E24: 1 | F24: 1 | G24: 1 | H24: 1 | I24: 1 | J24: 1 | K24: 1 | L24: 1 | M24: 1 | N24: 1 | O24: 1 | P24: 1 | Q24: 1 | R24: 1 | S24: 1 | T24: 1 | U24: 1 | V24: 1 | W24: 1 | X24: 1 | Y24: 1 | Z24: 1 | AA24: 1 | AB24: 1 | AC24: 1 | AD24: 1 | AE24: 1 | AF24: 1
A25: 24 | I25: 1 | J25: 1 | K25: 1 | L25: 1 | M25: 1
A26: 25 | B26: 1 | C26: 1 | D26: 1 | E26: 1 | F26: 1 | G26: 1 | H26: 1 | I26: 1 | J26: 1 | K26: 1 | L26: 1 | M26: 1 | N26: 1 | O26: 1 | P26: 1 | Q26: 1 | R26: 1 | S26: 1 | T26: 1 | U26: 1 | V26: 1 | W26: 1 | X26: 1 | Y26: 1 | Z26: 1 | AA26: 1 | AB26: 1 | AC26: 1 | AD26: 1 | AE26: 1 | AF26: 1
A27: 26
A28: 27 | AF28: 1
A29: 28 | U29: 1 | V29: 1
A30: 29 | N30: 1 | O30: 1 | P30: 1
A31: 30
A32: 31
A33: 32 | B33: 1 | C33: 1 | D33: 1 | E33: 1 | F33: 1 | G33: 1 | H33: 1 | I33: 1 | J33: 1 | AB33: 1
A34: 33 | H34: 1 | I34: 1 | V34: 1
A35: 34 | B35: 1 | C35: 1 | L35: 1 | M35: 1 | N35: 1 | O35: 1 | P35: 1 | Q35: 1 | R35: 1 | S35: 1 | T35: 1 | U35: 1 | V35: 1
A36: 35
A37: 36
A38: 37 | P38: 1 | T38: 1
A39: 38 | O39: 1
A40: 39 | W40: 1
...

Sheet EventReq
A1: =Events!B1 -> Event | B1: =Events!J1 -> Date | C1: =Employees!B2 -> Agnes Anna | D1: =Employees!B3 -> Alda/ Miðó | E1: =Employees!B4 -> Anna Soffía | F1: =Employees!B5 -> Arnar Ragn | G1: =Employees!B6 -> Auður | H1: =Employees!B7 -> Ágústa | I1: =Employees!B8 -> Daníel | J1: =Employees!B9 -> Elísabet | K1: =Employees!B10 -> Elmar | L1: =Employees!B11 -> Erna | M1: =Employees!B12 -> Gaukur | N1: =Employees!B13 -> Gréta | O1: =Employees!B14 -> Guðný | P1: =Employees!B15 -> Hólmfríður | Q1: =Employees!B16 -> Hrafnkell | R1: =Employees!B17 -> Hrannar | S1: =Employees!B18 -> Jórunn | T1: =Employees!B19 -> Katrín Hel | U1: =Employees!B20 -> Katrín Sig | V1: =Employees!B21 -> Laufey | W1: =Employees!B22 -> Magnea | X1: =Employees!B23 -> Magnús | Y1: =Employees!B24 -> Margrét Lára | Z1: =Employees!B25 -> Orri | AA1: =Employees!B26 -> Palli | AB1: =Employees!B27 -> Rut | AC1: =Employees!B28 -> Sara B | AD1: =Employees!B29 -> Sara Júlía | AE1: =Employees!B30 -> Selma | AF1: =Employees!B31 -> Sigríður | AG1: =Employees!B32 -> Sveinn | AH1: =Employees!B33 -> Sæmundur | AI1: =Employees!B34 -> Valdís | AJ1: =Employees!B35 -> Vero | AK1: =Employees!B36 -> Védís | AL1: =Employees!B37 -> Unnar | AM1: =Employees!B38 -> Ömmi | AN1: =Employees!B39 -> Arnar | AO1: =Employees!B40 -> Róbert | AP1: =Employees!B41 -> Jara | AQ1: =Employees!B42 -> Þórey
A2: =Events!B2 -> JS | B2: =Events!J2 -> 46082
A3: =Events!B3 -> Sinfó | B3: =Events!J3 -> 46086
A4: =Events!B4 -> Tón | B4: =Events!J4 -> 46086
A5: =Events!B5 -> RMF | B5: =Events!J5 -> 46087
A6: =Events!B6 -> HAM | B6: =Events!J6 -> 46087
A7: =Events!B7 -> IS | B7: =Events!J7 -> 46088
A8: =Events!B8 -> IS | B8: =Events!J8 -> 46088
A9: =Events!B9 -> PD | B9: =Events!J9 -> 46090
A10: =Events!B10 -> Sinfó | B10: =Events!J10 -> 46093
A11: =Events!B11 -> Sinfó | B11: =Events!J11 -> 46094
A12: =Events!B12 -> SB | B12: =Events!J12 -> 46094
A13: =Events!B13 -> GB | B13: =Events!J13 -> 46095
... A43: =Events!B43 -> RF | B43: =Events!J43 -> 46112

Sheet ScoreKeys
A1: RuleType | B1: Key | C1: Score
A2: Weekend | B2: 0 | C2: 50
A3: Weekend | B3: 1 | C3: 30
A4: Weekend | B4: 2 | C4: 15
A5: Weekend | B5: 3 | C5: -10
A6: Weekend | B6: 4 | C6: -50
A7: Weekend_last_period | B7: 0 | C7: 50
A8: Weekend_last_period | B8: 1 | C8: 25
A9: Weekend_last_period | B9: 2 | C9: 0
A10: Weekend_last_period | B10: 3 | C10: -25
A11: Weekend_last_period | B11: 4 | C11: -50
A12: Weekend_last_period | B12: 5 | C12: -60
A13: Hall | B13: 0 | C13: 20
... A26: Shifs_this_length | B26: 1 | C26: -1
A27: Shifs_this_length | B27: 2 | C27: =+C26*2 -> -2
A28: Shifs_this_length | B28: 3 | C28: =+C27*2 -> -4
A29: Shifs_this_length | B29: 4 | C29: =+C28*2 -> -8
A30: Shift_over_six_hours | B30: 1 | C30: -50
A31: Req_this_shift | B31: 1 | C31: 100
A32: Category | B32: 0 | C32: 20
A33: Category | B33: 1 | C33: 0
A34: Category | B34: 2 | C34: -20
A35: Category | B35: 3 | C35: -60
A36: Category | B36: 4 | C36: -100

Sheet SkillsetScores
A1: ReqSkillset | B1: EmpSkillset | C1: Score
A2: 1 | B2: 3 | C2: -10000
A3: 1 | B3: 2 | C3: -10000
A4: 2 | B4: 3 | C4: -200
A5: 2 | B5: 1 | C5: -50
A6: 3 | B6: 3 | C6: 100
A7: 2 | B7: 2 | C7: 100
A8: 1 | B8: 1 | C8: 100
A9: 3 | B9: 2 | C9: -200
A10: 3 | B10: 1 | C10: -200

Sheet EventTypes
A1: EventType | B1: EventCategory | C1: Hall | D1: EventRanking | E1: Skillset1 | F1: Skillset2 | G1: Employees
A2: Múlinn | B2: Solo | C2: BL | D2: 80 | E2: 0 | F2: 0 | G2: 1
A3: Barna EB | B3: Barna | C3: EB | D3: 70 | E3: 1 | F3: 2 | G3: 11
A4: Barna KL | B4: Barna | C4: KL | D4: 80 | E4: 0 | F4: 1 | G4: 2
A5: Sinfó | B5: Basic | C5: EB | D5: 50 | E5: 1 | F5: 3 | G5: 11
A6: EB | B6: Basic | C6: EB | D6: 70 | E6: 1 | F6: 4 | G6: 11
A7: How To | B7: Solo | C7: KL | D7: 100 | E7: 0 | F7: 0 | G7: 1
A8: Partý SB | B8: Party | C8: SB | D8: 70 | E8: 1 | F8: 2 | G8: 5
A9: Sígildir | B9: Solo | C9: NL | D9: 90 | E9: 0 | F9: 0 | G9: 1
A10: Partý EB | B10: Party | C10: EB | D10: 50 | E10: 1 | F10: 6 | G10: 11
A11: Fatahengi | B11: Fatahengi | C11: Fatahengi | D11: 80 | E11: 0 | F11: 0 | G11: 0
A12: SB | B12: Basic | C12: SB | D12: 80 | E12: 1 | F12: 1 | G12: 3
A13: KL | B13: Basic | C13: KL | D13: 40 | E13: 0 | F13: 1 | G13: 2
... A16: HH | B16: Solo | C16: HH | D16: 60 | E16: 0 | F16: 0 | G16: 1
